<?xml version="1.0" encoding="utf-8"?>
<!-- This URDF was automaticurdf_tutorialy created by SolidWorks to URDF Exporter! Originurdf_tutorialy created by Stephen Brawner (brawner@gmail.com) 
     Commit Version: 1.6.0-4-g7f85cfe  Build Version: 1.6.7995.38578
     For more information, please see http://wiki.ros.org/sw_urdf_exporter -->
<robot
  name="dog">
  <link
    name="base">
    <inertial>
      <origin
        xyz="9.86379408949578E-05 -0.000228650036753486 -0.00925201672369771"
        rpy="0 0 0" />
      <mass
        value="6.5" />
      <inertia
        ixx="0.02923472" 
        ixy="0.00303368"
        ixz="0.00001026"
        iyy="0.09103951"
        iyz="-0.00001899"
        izz="0.10914641" />
    </inertial>
    <visual>
      <origin
        xyz="0 0 0"
        rpy="0 0 0" />
      <geometry>
        <mesh
          filename="package://urdf_tutorial/meshes/base.STL" />
      </geometry>
      <material
        name="">
        <color
          rgba="0.752941176470588 0.752941176470588 0.752941176470588 1" />
      </material>
    </visual>
    <collision>
      <origin
        xyz="0 0 0"
        rpy="0 0 0" />
      <geometry>
        <box size="0.45 0.12 0.12" />
      </geometry>
    </collision>
  </link>
  <link
    name="FL_hip">
    <inertial>
      <origin
        xyz="-0.00478668991274023 1.90133511636797E-05 0.000220638398559413"
        rpy="0 0 0" />
      <mass
        value="1.06947979" />
      <inertia
        ixx="0.00055425"
        ixy="-0.00000628"
        ixz="0.00000110"
        iyy="0.00061490"
        iyz="-0.00000451"
        izz="0.00060205" />
    </inertial>
    <visual>
      <origin
        xyz="0 0 0"
        rpy="0 0 0" />
      <geometry>
        <mesh
          filename="package://urdf_tutorial/meshes/FL_hip.STL" />
      </geometry>
      <material
        name="">
        <color
          rgba="0.752941176470588 0.752941176470588 0.752941176470588 1" />
      </material>
    </visual>
    <collision>
      <origin rpy="1.5707963267948966 0 0" xyz="0 0.09 0" />
      <geometry>
        <cylinder length="0.05" radius="0.046" />
      </geometry>
    </collision>
  </link>
  <joint
    name="FL_hip_joint"
    type="revolute">
    <origin
      xyz="0.22337 0.06 0"
      rpy="0 0 0" />
    <parent
      link="base" />
    <child
      link="FL_hip" />
    <axis
      xyz="1 0 0" />
    <limit
      lower="-1.0"
      upper="1.0"
      effort="20."
      velocity="25." />
  </joint>
  <link
    name="FL_thigh">
    <inertial>
      <origin
        xyz="-0.00231149535394877 -0.0259576229949026 -0.0356321982318665"
        rpy="0 0 0" />
      <mass
        value="1.55793203" />
      <inertia
        ixx="0.03421799"
        ixy="0.00004973"
        ixz="-0.00028045"
        iyy="0.00573015"
        iyz="0.00102247"
        izz="0.00145693" />
    </inertial>
    <visual>
      <origin
        xyz="0 0 0"
        rpy="0 0 0" />
      <geometry>
        <mesh
          filename="package://urdf_tutorial/meshes/L_thigh.STL" />
      </geometry>
      <material
        name="">
        <color
          rgba="0.752941176470588 0.752941176470588 0.752941176470588 1" />
      </material>
    </visual>
    <collision>
      <origin rpy="0 1.5707963267948966 0" xyz="0 0 -0.1065" />
      <geometry>
        <box size="0.11 0.0245 0.034" />
      </geometry>
    </collision>
  </link>
  <joint
    name="FL_thigh_joint"
    type="revolute">
    <origin
      xyz="0 0.1039 0"
      rpy="0 0 0" />
    <parent
      link="FL_hip" />
    <child
      link="FL_thigh" />
    <axis
      xyz="0 1 0" />
    <limit
      lower="-1.5"
      upper="3.0"
      effort="20."
      velocity="25.0" />
  </joint>
  <link
    name="FL_calf">
    <inertial>
      <origin
        xyz="0.00602649928091619 -4.97049806039984E-05 -0.101341357290926"
        rpy="0 0 0" />
      <mass
        value="0.25295890" />
      <inertia
        ixx="0.03548797"
        ixy="0.00000006"
        ixz="0.00007904"
        iyy="0.04196517"
        iyz="0.00000196"
        izz="0.00003386" />
    </inertial>
    <visual>
      <origin
        xyz="0 0 0"
        rpy="0 0 0" />
      <geometry>
        <mesh
          filename="package://urdf_tutorial/meshes/calf.STL" />
      </geometry>
      <material
        name="">
        <color
          rgba="0.752941176470588 0.752941176470588 0.752941176470588 1" />
      </material>
    </visual>
    <collision>
      <origin rpy="0 -0.1 0" xyz="0.008 0 -0.08" />
      <geometry>
        <cylinder length="0.16" radius="0.0115" />
      </geometry>
    </collision>
  </link>
  <joint
    name="FL_calf_joint"
    type="revolute">
    <origin
      xyz="0 0 -0.22"
      rpy="0 0 0" />
    <parent
      link="FL_thigh" />
    <child
      link="FL_calf" />
    <axis
      xyz="0 1 0" />
    <limit
      lower="-2.5"
      upper="-0.85"
      effort="25."
      velocity="20.0" />
  </joint>
  <link
    name="FL_calflower">
    <collision>
      <origin rpy="0 -0.28  0" xyz="0 0 0.006" />
      <geometry>
        <cylinder length="0.05" radius="0.011" />
      </geometry>
    </collision>
  </link>
  <joint
    name="FL_calflower_joint"
    type="fixed">
    <origin
      xyz="0.016 0 -0.19"
      rpy="0 0.20787 0" />
    <parent
      link="FL_calf" />
    <child
      link="FL_calflower" />
    <axis
      xyz="0 0 0" />
  </joint>
  <link
    name="FL_calflower1">
    <collision>
      <origin rpy="0 0 0" xyz="0 0 0" />
      <geometry>
        <cylinder length="0.032" radius="0.0155" />
      </geometry>
    </collision>
  </link>
  <joint
    name="FL_calflower1_joint"
    type="fixed">
    <origin
      xyz="0 0 -0.03"
      rpy="0 0.2 0" />
    <parent
      link="FL_calflower" />
    <child
      link="FL_calflower1" />
    <axis
      xyz="0 0 0" />
  </joint>
  <link
    name="FL_foot">
    <inertial>
      <origin
        xyz="0 0 0"
        rpy="0 0 0" />
      <mass
        value="0.04" />
      <inertia
        ixx="9.6e-06"
        ixy="0"
        ixz="0"
        iyy="9.6e-06"
        iyz="0"
        izz="9.6e-06" />
    </inertial>
    <visual>
      <origin
        xyz="0 0 0"
        rpy="0 0 0" />
      <geometry>
        <mesh
          filename="package://urdf_tutorial/meshes/foot.stl" />
      </geometry>
      <material
        name="">
        <color
          rgba="1 1 1 1" />
      </material>
    </visual>
    <collision>
      <origin rpy="0 0 0" xyz="-0.002 0 0" />
      <geometry>
       <sphere radius="0.022" />
      </geometry>
    </collision>
  </link>
  <joint
    name="FL_foot_joint"
    type="fixed"  dont_collapse="true">
    <origin
      xyz="0 0 -0.24"
      rpy="0 0 0" />
    <parent
      link="FL_calf" />
    <child
      link="FL_foot" />
    <axis
      xyz="0 0 0" />
  </joint>
  <link
    name="FR_hip">
    <inertial>
      <origin
        xyz="0 0 0"
        rpy="0 0 0" />
      <mass
        value="1.06947979" />
      <inertia
        ixx="0.00055425"
        ixy="0.00000628"
        ixz="-0.00000110"
        iyy="0.00061490"
        iyz="-0.00000451"
        izz="0.00060205" />
    </inertial>
    <visual>
      <origin
        xyz="0 0 0"
        rpy="0 0 0" />
      <geometry>
        <mesh
          filename="package://urdf_tutorial/meshes/FR_hip.STL" />
      </geometry>
      <material
        name="">
        <color
          rgba="0.752941176470588 0.752941176470588 0.752941176470588 1" />
      </material>
    </visual>
    <collision>
      <origin rpy="1.5707963267948966 0 0" xyz="0 -0.09 0" />
      <geometry>
        <cylinder length="0.05" radius="0.046" />
      </geometry>
    </collision>
  </link>
  <joint
    name="FR_hip_joint"
    type="revolute">
    <origin
      xyz="0.22337 -0.06 0"
      rpy="0 0 0" />
    <parent
      link="base" />
    <child
      link="FR_hip" />
    <axis
      xyz="1 0 0" />
    <limit
      lower="-1.0"
      upper="1.0"
      effort="20."
      velocity="25." />
  </joint>
  <link
    name="FR_thigh">
    <inertial>
      <origin
        xyz="-0.00102167758546338 0.034785247828162 -0.0207384105629442"
        rpy="0 0 0" />
      <mass
        value="1.55793203" />
      <inertia
        ixx="0.00598563"
        ixy="-0.00005968"
        ixz="-0.00028819"
        iyy="0.00570709"
        iyz="-0.00101607"
        izz="0.00145163" />
    </inertial>
    <visual>
      <origin
        xyz="0 0 0"
        rpy="0 0 0" />
      <geometry>
        <mesh
          filename="package://urdf_tutorial/meshes/R_thigh.STL" />
      </geometry>
      <material
        name="">
        <color
          rgba="0.752941176470588 0.752941176470588 0.752941176470588 1" />
      </material>
    </visual>
    <collision>
       <origin rpy="0 1.5707963267948966 0" xyz="0 0 -0.1065" />
      <geometry>
        <box size="0.11 0.0245 0.034" />
      </geometry>
    </collision>
  </link>
  <joint
    name="FR_thigh_joint"
    type="revolute">
    <origin
      xyz="0 -0.1039 0"
      rpy="0 0 0" />
    <parent
      link="FR_hip" />
    <child
      link="FR_thigh" />
    <axis
      xyz="0 1 0" />
    <limit
      lower="-1.5"
      upper="3.0"
      effort="20."
      velocity="25.0" />
  </joint>
  <link
    name="FR_calf">
    <inertial>
      <origin
        xyz="0.00602649927812829 -4.97049812005768E-05 -0.10134135729045"
        rpy="0 0 0" />
      <mass
        value="0.25295890" />
      <inertia
        ixx="0.03550390"
        ixy="0.00000006"
        ixz="0.00007904"
        iyy="0.04194821"
        iyz="-0.00000196"
        izz="0.00003386" />
    </inertial>
    <visual>
      <origin
        xyz="0 0 0"
        rpy="0 0 0" />
      <geometry>
        <mesh
          filename="package://urdf_tutorial/meshes/calf.STL" />
      </geometry>
      <material
        name="">
        <color
          rgba="0.752941176470588 0.752941176470588 0.752941176470588 1" />
      </material>
    </visual>
    <collision>
      <origin rpy="0 -0.1 0" xyz="0.008 0 -0.08" />
      <geometry>
         <cylinder length="0.16" radius="0.0115" />
      </geometry>
    </collision>
  </link>
  <joint
    name="FR_calf_joint"
    type="revolute">
    <origin
      xyz="0 0 -0.22"
      rpy="0 0 0" />
    <parent
      link="FR_thigh" />
    <child
      link="FR_calf" />
    <axis
      xyz="0 1 0" />
    <limit
      lower="-2.5"
      upper="-0.85"
      effort="25."
      velocity="20.0" />
  </joint>
  <link
    name="FR_calflower">
    <collision>
      <origin rpy="0 -0.28  0" xyz="0 0 0.006" />
      <geometry>
        <cylinder length="0.05" radius="0.011" />
      </geometry>
    </collision>
  </link>
  <joint
    name="FR_calflower_joint"
    type="fixed">
    <origin
      xyz="0.016 0 -0.19"
      rpy="0 0.20787 0" />
    <parent
      link="FR_calf" />
    <child
      link="FR_calflower" />
    <axis
      xyz="0 0 0" />
  </joint>
  <link
    name="FR_calflower1">
    <collision>
      <origin rpy="0 0 0" xyz="0 0 0" />
      <geometry>
        <cylinder length="0.032" radius="0.0155" />
      </geometry>
    </collision>
  </link>
  <joint
    name="FR_calflower1_joint"
    type="fixed">
    <origin
      xyz="0 0 -0.03"
      rpy="0 0.2 0" />
    <parent
      link="FR_calflower" />
    <child
      link="FR_calflower1" />
    <axis
      xyz="0 0 0" />
  </joint>
  <link
    name="FR_foot">
    <inertial>
      <origin
        xyz="0 0 0"
        rpy="0 0 0" />
      <mass
        value="0.04" />
      <inertia
        ixx="9.6e-06"
        ixy="0"
        ixz="0"
        iyy="9.6e-06"
        iyz="0"
        izz="9.6e-06" />
    </inertial>
    <visual>
      <origin
        xyz="0 0 0"
        rpy="0 0 0" />
      <geometry>
        <mesh
          filename="package://urdf_tutorial/meshes/foot.stl" />
      </geometry>
      <material
        name="">
        <color
          rgba="1 1 1 1" />
      </material>
    </visual>
    <collision>
      <origin rpy="0 0 0" xyz="-0.002 0 0" />
      <geometry>
        <sphere radius="0.022" />
      </geometry>
    </collision>
  </link>
  <joint
    name="FR_foot_joint"
    type="fixed"  dont_collapse="true">
    <origin
      xyz="0 0 -0.24"
      rpy="0 0 0" />
    <parent
      link="FR_calf" />
    <child
      link="FR_foot" />
    <axis
      xyz="0 0 0" />
  </joint>
  <link
    name="RL_hip">
    <inertial>
      <origin
        xyz="0.00478668991693643 1.87932525216594E-05 -0.000220657252609686"
        rpy="0 0 0" />
      <mass
        value="1.06947979" />
      <inertia
        ixx="0.00055425"
        ixy="0.00000628"
        ixz="0.00000109"
        iyy="0.00061490"
        iyz="0.00000450"
        izz="0.00060204" />
    </inertial>
    <visual>
      <origin
        xyz="0 0 0"
        rpy="0 0 0" />
      <geometry>
        <mesh
          filename="package://urdf_tutorial/meshes/RL_hip.STL" />
      </geometry>
      <material
        name="">
        <color
          rgba="0.752941176470588 0.752941176470588 0.752941176470588 1" />
      </material>
    </visual>
    <collision>
      <origin rpy="1.5707963267948966 0 0" xyz="0 0.09 0" />
      <geometry>
        <cylinder length="0.05" radius="0.046" />
      </geometry>
    </collision>
  </link>
  <joint
    name="RL_hip_joint"
    type="revolute">
    <origin
      xyz="-0.22337 0.06 0"
      rpy="0 0 0" />
    <parent
      link="base" />
    <child
      link="RL_hip" />
    <axis
      xyz="1 0 0" />
    <limit
      lower="-1.0"
      upper="1.0"
      effort="20."
      velocity="25." />
  </joint>
  <link
    name="RL_thigh">
    <inertial>
      <origin
        xyz="-0.00245812847176474 -0.0259575608404084 -0.0351973722540475"
        rpy="0 0 0" />
      <mass
        value="1.55025095" />
      <inertia
        ixx="0.00568291"
        ixy="0.00005580"
        ixz="-0.00028389"
        iyy="0.00540994"
        iyz="0.00096745"
        izz="0.00144723" />
    </inertial>
    <visual>
      <origin
        xyz="0 0 0"
        rpy="0 0 0" />
      <geometry>
        <mesh
          filename="package://urdf_tutorial/meshes/L_thigh.STL" />
      </geometry>
      <material
        name="">
        <color
          rgba="0.752941176470588 0.752941176470588 0.752941176470588 1" />
      </material>
    </visual>
    <collision>
      <origin rpy="0 1.5707963267948966 0" xyz="0 0 -0.1065" />
      <geometry>
        <box size="0.11 0.0245 0.034" />
      </geometry>
    </collision>
  </link>
  <joint
    name="RL_thigh_joint"
    type="revolute">
    <origin
      xyz="0 0.1039 0"
      rpy="0 0 0" />
    <parent
      link="RL_hip" />
    <child
      link="RL_thigh" />
    <axis
      xyz="0 1 0" />
    <limit
      lower="-1.5"
      upper="3.0"
      effort="20."
      velocity="25.0" />
  </joint>
  <link
    name="RL_calf">
    <inertial>
      <origin
        xyz="0.00602649937159078 -4.97048694773905E-05 -0.101341356161322"
        rpy="0 0 0" />
      <mass
        value="0.25295890" />
      <inertia
        ixx="0.00222364"
        ixy="0.00000006"
        ixz="0.00007904"
        iyy="0.00223396"
        iyz="-0.00000196"
        izz="0.00003386" />
    </inertial>
    <visual>
      <origin
        xyz="0 0 0"
        rpy="0 0 0" />
      <geometry>
        <mesh
          filename="package://urdf_tutorial/meshes/calf.STL" />
      </geometry>
      <material
        name="">
        <color
          rgba="0.752941176470588 0.752941176470588 0.752941176470588 1" />
      </material>
    </visual>
    <collision>
      <origin rpy="0 -0.1 0" xyz="0.008 0 -0.08" />
      <geometry>
        <cylinder length="0.16" radius="0.0115" />
      </geometry>
    </collision>
  </link>
  <joint
    name="RL_calf_joint"
    type="revolute">
    <origin
      xyz="0 0 -0.22"
      rpy="0 0 0" />
    <parent
      link="RL_thigh" />
    <child
      link="RL_calf" />
    <axis
      xyz="0 1 0" />
    <limit
      lower="-2.5"
      upper="-0.85"
      effort="25."
      velocity="20.0" />
  </joint>
  <link
    name="RL_calflower">
    <collision>
      <origin rpy="0 -0.28  0" xyz="0 0 0.006" />
      <geometry>
        <cylinder length="0.05" radius="0.011" />
      </geometry>
    </collision>
  </link>
  <joint
    name="RL_calflower_joint"
    type="fixed">
    <origin
      xyz="0.016 0 -0.19"
      rpy="0 0.20787 0" />
    <parent
      link="RL_calf" />
    <child
      link="RL_calflower" />
    <axis
      xyz="0 0 0" />
  </joint>
  <link
    name="RL_calflower1">
   <collision>
      <origin rpy="0 0 0" xyz="0 0 0" />
      <geometry>
        <cylinder length="0.032" radius="0.0155" />
      </geometry>
    </collision>
  </link>
  <joint
    name="RL_calflower1_joint"
    type="fixed">
    <origin
      xyz="0 0 -0.03"
      rpy="0 0.2 0" />
    <parent
      link="RL_calflower" />
    <child
      link="RL_calflower1" />
    <axis
      xyz="0 0 0" />
  </joint>
  <link
    name="RL_foot">
    <inertial>
      <origin
        xyz="0 0 0"
        rpy="0 0 0" />
      <mass
        value="0.04" />
      <inertia
        ixx="9.6e-06"
        ixy="0"
        ixz="0"
        iyy="9.6e-06"
        iyz="0"
        izz="9.6e-06" />
    </inertial>
    <visual>
      <origin
        xyz="0 0 0"
        rpy="0 0 0" />
      <geometry>
        <mesh
          filename="package://urdf_tutorial/meshes/foot.stl" />
      </geometry>
      <material
        name="">
        <color
          rgba="1 1 1 1" />
      </material>
    </visual>
    <collision>
      <origin rpy="0 0 0" xyz="-0.002 0 0" />
      <geometry>
        <sphere radius="0.022" />
      </geometry>
    </collision>
  </link>
  <joint
    name="RL_foot_joint"
    type="fixed">
    <origin
      xyz="0 0 -0.24"
      rpy="0 0 0" />
    <parent
      link="RL_calf" />
    <child
      link="RL_foot" />
    <axis
      xyz="0 0 0" />
  </joint>
  <link
    name="RR_hip">
    <inertial>
      <origin
        xyz="0 0 0"
        rpy="0 0 0" />
      <mass
        value="1.06947979" />
      <inertia
        ixx="0.00055425"
        ixy="-0.00000628"
        ixz="-0.00000109"
        iyy="0.00061491"
        iyz="0.00000450"
        izz="0.00060204" />
    </inertial>
    <visual>
      <origin
        xyz="0 0 0"
        rpy="0 0 0" />
      <geometry>
        <mesh
          filename="package://urdf_tutorial/meshes/RR_hip.STL" />
      </geometry>
      <material
        name="">
        <color
          rgba="1 1 1 1" />
      </material>
    </visual>
    <collision>
      <origin rpy="1.5707963267948966 0 0" xyz="0 -0.09 0" />
      <geometry>
        <cylinder length="0.05" radius="0.046" />
      </geometry>
    </collision>
  </link>
  <joint
    name="RR_hip_joint"
    type="revolute">
    <origin
      xyz="-0.22337 -0.06 0"
      rpy="0 0 0" />
    <parent
      link="base" />
    <child
      link="RR_hip" />
    <axis
      xyz="1 0 0" />
    <limit
      lower="-1.0"
      upper="1.0"
      effort="20."
      velocity="25." />
  </joint>
  <link
    name="RR_thigh">
    <inertial>
      <origin
        xyz="-0.000904252480658896 0.0347851323626063 -0.0209699339939975"
        rpy="0 0 0" />
      <mass
        value="1.55005095" />
      <inertia
        ixx="0.00568495"
        ixy="-0.00005831"
        ixz="-0.00028980"
        iyy="0.00541375"
        iyz="-0.00097460"
        izz="0.00145089" />
    </inertial>
    <visual>
      <origin
        xyz="0 0 0"
        rpy="0 0 0" />
      <geometry>
        <mesh
          filename="package://urdf_tutorial/meshes/R_thigh.STL" />
      </geometry>
      <material
        name="">
        <color
          rgba="0.752941176470588 0.752941176470588 0.752941176470588 1" />
      </material>
    </visual>
    <collision>
      <origin rpy="0 1.5707963267948966 0" xyz="0 0 -0.1065" />
      <geometry>
        <box size="0.11 0.0245 0.034" />
      </geometry>
    </collision>
  </link>
  <joint
    name="RR_thigh_joint"
    type="revolute">
    <origin
      xyz="0 -0.1039 0"
      rpy="0 0 0" />
    <parent
      link="RR_hip" />
    <child
      link="RR_thigh" />
    <axis
      xyz="0 1 0" />
    <limit
      lower="-1.5"
      upper="3.0"
      effort="20."
      velocity="25.0" />
  </joint>
  <link
    name="RR_calf">
    <inertial>
      <origin
        xyz="0.00602649937802247 -4.97048678604894E-05 -0.101341356232684"
        rpy="0 0 0" />
      <mass
        value="0.25295890" />
      <inertia
        ixx="0.00222364"
        ixy="0.00000006"
        ixz="0.00007904"
        iyy="0.00223396"
        iyz="-0.00000196"
        izz="0.00003386" />
    </inertial>
    <visual>
      <origin
        xyz="0 0 0"
        rpy="0 0 0" />
      <geometry>
        <mesh
          filename="package://urdf_tutorial/meshes/calf.STL" />
      </geometry>
      <material
        name="">
        <color
          rgba="0.752941176470588 0.752941176470588 0.752941176470588 1" />
      </material>
    </visual>
    <collision>
      <origin rpy="0 -0.1 0" xyz="0.008 0 -0.08" />
      <geometry>
         <cylinder length="0.16" radius="0.0115" />
      </geometry>
    </collision>
  </link>
  <joint
    name="RR_calf_joint"
    type="revolute">
    <origin
      xyz="0 0 -0.22"
      rpy="0 0 0" />
    <parent
      link="RR_thigh" />
    <child
      link="RR_calf" />
    <axis
      xyz="0 1 0" />
    <limit
      lower="-2.5"
      upper="-0.85"
      effort="25."
      velocity="20.0" />
  </joint>
  <link
    name="RR_calflower">
       <collision>
      <origin rpy="0 -0.28  0" xyz="0 0 0.006" />
      <geometry>
        <cylinder length="0.05" radius="0.011" />
      </geometry>
    </collision>
  </link>
  <joint
    name="RR_calflower_joint"
    type="fixed">
    <origin
      xyz="0.01623 0 -0.19038"
      rpy="0 0.20787 0" />
    <parent
      link="RR_calf" />
    <child
      link="RR_calflower" />
    <axis
      xyz="0 0 0" />
  </joint>
  <link
    name="RR_calflower1">
    <collision>
      <origin rpy="0 0 0" xyz="0 0 0" />
      <geometry>
        <cylinder length="0.032" radius="0.0155" />
      </geometry>
    </collision>
  </link>
  <joint
    name="RR_calflower1_joint"
    type="fixed">
    <origin
      xyz="0 0 -0.03"
      rpy="0 0.2 0" />
    <parent
      link="RR_calflower" />
    <child
      link="RR_calflower1" />
    <axis
      xyz="0 0 0" />
  </joint>
  <link
    name="RR_foot">
    <inertial>
      <origin
        xyz="0 0 0"
        rpy="0 0 0" />
      <mass
        value="0.04" />
      <inertia
        ixx="9.6e-06"
        ixy="0"
        ixz="0"
        iyy="9.6e-06"
        iyz="0"
        izz="9.6e-06" />
    </inertial>
    <visual>
      <origin
        xyz="0 0 0"
        rpy="0 0 0" />
      <geometry>
        <mesh
          filename="package://urdf_tutorial/meshes/foot.stl" />
      </geometry>
      <material
        name="">
        <color
          rgba="1 1 1 1" />
      </material>
    </visual>
    <collision>
      <origin rpy="0 0 0" xyz="-0.002 0 0" />
      <geometry>
        <sphere radius="0.022" />
      </geometry>
    </collision>
  </link>
  <joint
    name="RR_foot_joint"
    type="fixed" dont_collapse="true">
    <origin
      xyz="0 0 -0.24"
      rpy="0 0 0" />
    <parent
      link="RR_calf" />
    <child
      link="RR_foot" />
    <axis
      xyz="0 0 0" />
  </joint>
  <link
    name="imu">
    <inertial>
      <origin
        xyz="0 0 0"
        rpy="0 0 0" />
      <mass
        value="0" />
      <inertia
        ixx="0"
        ixy="0"
        ixz="0"
        iyy="0"
        iyz="0"
        izz="0" />
    </inertial>
  </link>
  <joint
    name="imu_joint"
    type="fixed">
    <origin
      xyz="-0.02557 0 0.04232"
      rpy="0 0 0" />
    <parent
      link="base" />
    <child
      link="imu" />
    <axis
      xyz="0 0 0" />
  </joint>
</robot>