<?xml version="1.0" encoding="utf-8"?>
<!-- This URDF was automatically created by SolidWorks to URDF Exporter! Originally created by Stephen Brawner (brawner@gmail.com) 
     Commit Version: 1.6.0-4-g7f85cfe  Build Version: 1.6.7995.38578
     For more information, please see http://wiki.ros.org/sw_urdf_exporter -->
<robot
  name="dog">
  <link
    name="base">
    <inertial>
      <origin
        xyz="-0.00349256695864725 0 -0.0103465291224879"
        rpy="0 0 0" />
      <mass
        value="4.14793773965226" />
      <inertia
        ixx="0.00697550287250648"
        ixy="-2.79982098431838E-05"
        ixz="-1.36369765678284E-06"
        iyy="0.0120276297018984"
        iyz="3.91177180473726E-06"
        izz="0.0146711469908447" />
    </inertial>
    <visual>
      <origin
        xyz="0 0 0"
        rpy="0 0 0" />
      <geometry>
        <mesh
          filename="package://urdf_tutorial/meshes/TOE_dog3/base.STL" />
      </geometry>
      <material
        name="">
        <color
          rgba="1 1 1 1" />
      </material>
    </visual>
    <collision>
      <origin
        xyz="0 0 0"
        rpy="0 0 0" />
      <geometry>
       <box size="0.277 0.12 0.12" />
      </geometry>
    </collision>
  </link>
  <link
    name="FL_hip">
    <inertial>
      <origin
        xyz="0.0544563981000604 -0.0122230494548459 -3.33185672222458E-05"
        rpy="0 0 0" />
      <mass
        value="0.333458397585496" />
      <inertia
        ixx="0.000228898292882318"
        ixy="5.63887073816656E-06"
        ixz="6.00777019593683E-08"
        iyy="0.000358700855387494"
        iyz="-2.45226678637971E-07"
        izz="0.000209164381438417" />
    </inertial>
    <visual>
      <origin
        xyz="0 0 0"
        rpy="0 0 0" />
      <geometry>
        <mesh
          filename="package://urdf_tutorial/meshes/TOE_dog3/FL_hip.STL" />
      </geometry>
      <material
        name="">
        <color
          rgba="1 1 1 1" />
      </material>
    </visual>
    <collision>
      <origin rpy="1.5707963267948966 0 0" xyz="0.064 0.0 0" />
      <geometry>
        <cylinder length="0.08" radius="0.048" />
      </geometry>
    </collision>
  </link>
  <joint
    name="FL_hip_joint"
    type="revolute">
    <origin
      xyz="0.138 0.063 0"
      rpy="0 0 0" />
    <parent
      link="base" />
    <child
      link="FL_hip" />
    <axis
      xyz="1 0 0" />
    <limit
      lower="-1.0"
      upper="1.0"
      effort="20."
      velocity="20." />
  </joint>
  <link
    name="FL_thigh">
    <inertial>
      <origin
        xyz="-0.00209130800270174 -0.0157512217881884 -0.0357313445456687"
        rpy="0 0 0" />
      <mass
        value="0.597899900355259" />
      <inertia
        ixx="0.00175523965312692"
        ixy="-3.65851144353315E-07"
        ixz="-8.02876202523007E-05"
        iyy="0.00206830476129784"
        iyz="-1.82714772017471E-06"
        izz="0.000358526326399745" />
    </inertial>
    <visual>
      <origin
        xyz="0 0 0"
        rpy="0 0 0" />
      <geometry>
        <mesh
          filename="package://urdf_tutorial/meshes/TOE_dog3/FL_thigh.STL" />
      </geometry>
      <material
        name="">
        <color
          rgba="1 1 1 1" />
      </material>
    </visual>
    <collision>
      <origin rpy="0 1.5707963267948966 0" xyz="0 0 -0.1065" />
      <geometry>
        <box size="0.11 0.0245 0.034" />
      </geometry>
    </collision>
  </link>
  <joint
    name="FL_thigh_joint"
    type="revolute">
    <origin
      xyz="0.064 0.0673 0"
      rpy="0 0 0" />
    <parent
      link="FL_hip" />
    <child
      link="FL_thigh" />
    <axis
      xyz="0 1 0" />
    <limit
      lower="-1.5"
      upper="2.5"
      effort="30."
      velocity="32.0" />
  </joint>
  <link
    name="FL_calf">
    <inertial>
      <origin
        xyz="0.008656739122546 -4.16362152565741E-05 -0.0952663894238618"
        rpy="0 0 0" />
      <mass
        value="0.160684138940378" />
      <inertia
        ixx="0.000298759609040333"
        ixy="1.45139114640267E-08"
        ixz="2.43022230389108E-05"
        iyy="0.000309017747432367"
        iyz="4.73319001595361E-08"
        izz="1.56084268840691E-05" />
    </inertial>
    <visual>
      <origin
        xyz="0 0 0"
        rpy="0 0 0" />
      <geometry>
        <mesh
          filename="package://urdf_tutorial/meshes/TOE_dog3/FL_calf.STL" />
      </geometry>
      <material
        name="">
        <color
          rgba="1 1 1 1" />
      </material>
    </visual>
    <collision>
      <origin rpy="0 -0.21 0" xyz="0.008 0 -0.06" />
      <geometry>
        <cylinder length="0.12" radius="0.012" />
      </geometry>
    </collision>
  </link>
  <joint
    name="FL_calf_joint"
    type="revolute">
    <origin
      xyz="0 0 -0.2"
      rpy="0 0 0" />
    <parent
      link="FL_thigh" />
    <child
      link="FL_calf" />
    <axis
      xyz="0 1 0" />
    <limit
      lower="-2.5"
      upper="-0.85"
      effort="35."
      velocity="32.0" />
  </joint>
  <link
    name="FL_calflower">

    <collision>
      <origin rpy="0 0 0" xyz="0 0 0" />
      <geometry>
        <cylinder length="0.065" radius="0.011" />
      </geometry>
    </collision>
  </link>
  <joint
    name="FL_calflower_joint"
    type="fixed">
    <origin
      xyz="0.020 0 -0.148"
      rpy="0 0.05 0" />
    <parent
      link="FL_calf" />
    <child
      link="FL_calflower" />
    <axis
      xyz="0 0 0" />
  </joint>
  <link
    name="FL_calflower1">
    <collision>
      <origin rpy="0 0 0" xyz="0 0 0.001" />
      <geometry>
        <cylinder length="0.03" radius="0.0155" />
      </geometry>
    </collision>
  </link>
  <joint
    name="FL_calflower1_joint"
    type="fixed">
    <origin
      xyz="-0.01 0 -0.04"
      rpy="0 0.48 0" />
    <parent
      link="FL_calflower" />
    <child
      link="FL_calflower1" />
    <axis
      xyz="0 0 0" />
  </joint>
  <link
    name="FL_foot">
    <inertial>
      <origin
        xyz="0 0 0"
        rpy="0 0 0" />
      <mass
        value="0.04" />
      <inertia
        ixx="9.6e-06"
        ixy="0"
        ixz="0"
        iyy="9.6e-06"
        iyz="0"
        izz="9.6e-06" />
    </inertial>
    <visual>
      <origin
        xyz="0 0 0"
        rpy="0 0 0" />
      <geometry>
        <mesh
            filename="package://urdf_tutorial/meshes/foot.stl" />
      </geometry>
      <material
        name="">
        <color
          rgba="1 1 1 1" />
      </material>
    </visual>
    <collision>
      <origin rpy="0 0 0" xyz="-0.002 0 0" />
      <geometry>
        <sphere radius="0.022" />
      </geometry>
    </collision>
  </link>
  <joint
    name="FL_foot_joint"
    type="fixed" dont_collapse="true">
    <origin
      xyz="0 0 -0.2112"
      rpy="0 0 0" />
    <parent
      link="FL_calf" />
    <child
      link="FL_foot" />
    <axis
      xyz="0 0 0" />
  </joint>
  <link
    name="FR_hip">
    <inertial>
      <origin
        xyz="0.0544563981000606 0.0122230494548458 3.33185672212188E-05"
        rpy="0 0 0" />
      <mass
        value="0.333458397585498" />
      <inertia
        ixx="0.000228898292882319"
        ixy="-5.63887073816523E-06"
        ixz="-6.00777019592976E-08"
        iyy="0.000358700855387495"
        iyz="-2.45226678638358E-07"
        izz="0.000209164381438418" />
    </inertial>
    <visual>
      <origin
        xyz="0 0 0"
        rpy="0 0 0" />
      <geometry>
        <mesh
          filename="package://urdf_tutorial/meshes/TOE_dog3/FR_hip.STL" />
      </geometry>
      <material
        name="">
        <color
          rgba="1 1 1 1" />
      </material>
    </visual>
    <collision>
      <origin rpy="1.5707963267948966 0 0" xyz="0.064 0.0 0" />
      <geometry>
        <cylinder length="0.08" radius="0.048" />
      </geometry>
    </collision>
  </link>
  <joint
    name="FR_hip_joint"
    type="revolute">
    <origin
      xyz="0.138 -0.063 0"
      rpy="0 0 0" />
    <parent
      link="base" />
    <child
      link="FR_hip" />
    <axis
      xyz="1 0 0" />
    <limit
      lower="-1.0"
      upper="1.0"
      effort="20."
      velocity="20." />
  </joint>
  <link
    name="FR_thigh">
    <inertial>
      <origin
        xyz="-0.00179872498750472 0.0157556929216269 -0.036136855994278"
        rpy="0 0 0" />
      <mass
        value="0.597702170804917" />
      <inertia
        ixx="0.00175679023858682"
        ixy="3.76366543901474E-07"
        ixz="-8.03965188716408E-05"
        iyy="0.00206828718878731"
        iyz="2.31975014127829E-06"
        izz="0.000356956578939611" />
    </inertial>
    <visual>
      <origin
        xyz="0 0 0"
        rpy="0 0 0" />
      <geometry>
        <mesh
          filename="package://urdf_tutorial/meshes/TOE_dog3/RR_thigh.STL" />
      </geometry>
      <material
        name="">
        <color
          rgba="1 1 1 1" />
      </material>
    </visual>
    <collision>
      <origin rpy="0 1.5707963267948966 0" xyz="0 0 -0.1065" />
      <geometry>
        <box size="0.11 0.0245 0.034" />
      </geometry>
    </collision>
  </link>
  <joint
    name="FR_thigh_joint"
    type="revolute">
    <origin
      xyz="0.064 -0.0673 0"
      rpy="0 0 0" />
    <parent
      link="FR_hip" />
    <child
      link="FR_thigh" />
    <axis
      xyz="0 1 0" />
    <limit
      lower="-1.5"
      upper="2.5"
      effort="30."
      velocity="32.0" />
  </joint>
  <link
    name="FR_calf">
    <inertial>
      <origin
        xyz="0.00865673912254511 0 -0.0952663894238544"
        rpy="0 0 0" />
      <mass
        value="0.160684138940368" />
      <inertia
        ixx="0.000298759609040427"
        ixy="1.45139114638068E-08"
        ixz="2.43022230390168E-05"
        iyy="0.000309017747432508"
        iyz="4.73319001600016E-08"
        izz="1.56084268841167E-05" />
    </inertial>
    <visual>
      <origin
        xyz="0 0 0"
        rpy="0 0 0" />
      <geometry>
        <mesh
          filename="package://urdf_tutorial/meshes/TOE_dog3/FR_calf.STL" />
      </geometry>
      <material
        name="">
        <color
          rgba="1 1 1 1" />
      </material>
    </visual>
    <collision>
      <origin rpy="0 -0.2 0" xyz="0.01 0 -0.06" />
      <geometry>
        <cylinder length="0.12" radius="0.013" />
      </geometry>
    </collision>
  </link>
  <joint
    name="FR_calf_joint"
    type="revolute">
    <origin
      xyz="0 0 -0.2"
      rpy="0 0 0" />
    <parent
      link="FR_thigh" />
    <child
      link="FR_calf" />
    <axis
      xyz="0 1 0" />
    <limit
      lower="-2.5"
      upper="-0.85"
      effort="35."
      velocity="32.0" />
  </joint>
  <link
    name="FR_calflower">
      <collision>
      <origin rpy="0 0 0" xyz="0 0 0" />
      <geometry>
        <cylinder length="0.065" radius="0.011" />
      </geometry>
    </collision>
  </link>
  <joint
    name="FR_calflower_joint"
    type="fixed">
    <origin
      xyz="0.020 0 -0.148"
      rpy="0 0.05 0" />
    <parent
      link="FR_calf" />
    <child
      link="FR_calflower" />
    <axis
      xyz="0 0 0" />
  </joint>
  <link
    name="FR_calflower1">
    <collision>
      <origin rpy="0 0 0" xyz="0 0 0.001" />
      <geometry>
        <cylinder length="0.03" radius="0.0155" />
      </geometry>
    </collision>
  </link>
  <joint
    name="FR_calflower1_joint"
    type="fixed">
    <origin
      xyz="-0.01 0 -0.04"
      rpy="0 0.48 0" />
    <parent
      link="FR_calflower" />
    <child
      link="FR_calflower1" />
    <axis
      xyz="0 0 0" />
  </joint>
  <link
    name="FR_foot">
    <inertial>
      <origin
        xyz="0 0 0"
        rpy="0 0 0" />
      <mass
        value="0.04" />
      <inertia
        ixx="9.6e-06"
        ixy="0"
        ixz="0"
        iyy="9.6e-06"
        iyz="0"
        izz="9.6e-06" />
    </inertial>
    <visual>
      <origin
        xyz="0 0 0"
        rpy="0 0 0" />
      <geometry>
        <mesh
          filename="package://urdf_tutorial/meshes/foot.stl" />
      </geometry>
      <material
        name="">
        <color
          rgba="1 1 1 1" />
      </material>
    </visual>
    <collision>
      <origin rpy="0 0 0" xyz="-0.002 0 0" />
      <geometry>
        <sphere radius="0.022" />
      </geometry>
    </collision>
  </link>
  <joint
    name="FR_foot_joint"
    type="fixed" dont_collapse="true">
    <origin
      xyz="0 0 -0.2112"
      rpy="0 0 0" />
    <parent
      link="FR_calf" />
    <child
      link="FR_foot" />
    <axis
      xyz="0 0 0" />
  </joint>
  <link
    name="RL_hip">
    <inertial>
      <origin
        xyz="-0.0544563980901655 -0.0122230494514425 3.331856620023E-05"
        rpy="0 0 0" />
      <mass
        value="0.333458397795883" />
      <inertia
        ixx="0.000228898292913372"
        ixy="-5.63887079795713E-06"
        ixz="6.00777112907115E-08"
        iyy="0.000358700855536296"
        iyz="2.45226682486442E-07"
        izz="0.00020916438160646" />
    </inertial>
    <visual>
      <origin
        xyz="0 0 0"
        rpy="0 0 0" />
      <geometry>
        <mesh
          filename="package://urdf_tutorial/meshes/TOE_dog3/RL_hip.STL" />
      </geometry>
      <material
        name="">
        <color
          rgba="1 1 1 1" />
      </material>
    </visual>
    <collision>
      <origin rpy="1.5707963267948966 0 0" xyz="-0.064 0.0 0" />
      <geometry>
        <cylinder length="0.08" radius="0.048" />
      </geometry>
    </collision>
  </link>
  <joint
    name="RL_hip_joint"
    type="revolute">
    <origin
      xyz="-0.136 0.063 0"
      rpy="0 0 0" />
    <parent
      link="base" />
    <child
      link="RL_hip" />
    <axis
      xyz="1 0 0" />
    <limit
      lower="-1.0"
      upper="1.0"
      effort="20."
      velocity="20." />
  </joint>
  <link
    name="RL_thigh">
    <inertial>
      <origin
        xyz="-0.00209130801473683 -0.0157512217880365 -0.0357313445606814"
        rpy="0 0 0" />
      <mass
        value="0.597899900088883" />
      <inertia
        ixx="0.0017552396530875"
        ixy="-3.65851069163829E-07"
        ixz="-8.02876202673877E-05"
        iyy="0.00206830476111155"
        iyz="-1.82714772619961E-06"
        izz="0.000358526326189467" />
    </inertial>
    <visual>
      <origin
        xyz="0 0 0"
        rpy="0 0 0" />
      <geometry>
        <mesh
          filename="package://urdf_tutorial/meshes/TOE_dog3/RL_thigh.STL" />
      </geometry>
      <material
        name="">
        <color
          rgba="1 1 1 1" />
      </material>
    </visual>
    <collision>
      <origin rpy="0 1.5707963267948966 0" xyz="0 0 -0.1065" />
      <geometry>
        <box size="0.11 0.0245 0.034" />
      </geometry>
    </collision>
  </link>
  <joint
    name="RL_thigh_joint"
    type="revolute">
    <origin
      xyz="-0.064 0.0673 0"
      rpy="0 0 0" />
    <parent
      link="RL_hip" />
    <child
      link="RL_thigh" />
    <axis
      xyz="0 1 0" />
    <limit
      lower="-1.5"
      upper="2.5"
      effort="30."
      velocity="32.0" />
  </joint>
  <link
    name="RL_calf">
    <inertial>
      <origin
        xyz="0.00865673912254477 -4.16362152587946E-05 -0.095266389423857"
        rpy="0 0 0" />
      <mass
        value="0.160684138940364" />
      <inertia
        ixx="0.000298759609040318"
        ixy="1.45139114640389E-08"
        ixz="2.43022230387527E-05"
        iyy="0.000309017747432171"
        iyz="4.73319001595981E-08"
        izz="1.56084268838885E-05" />
    </inertial>
    <visual>
      <origin
        xyz="0 0 0"
        rpy="0 0 0" />
      <geometry>
        <mesh
          filename="package://urdf_tutorial/meshes/TOE_dog3/RL_calf.STL" />
      </geometry>
      <material
        name="">
        <color
          rgba="0.752941176470588 0.752941176470588 0.752941176470588 1" />
      </material>
    </visual>
    <collision>
      <origin rpy="0 -0.2 0" xyz="0.01 0 -0.06" />
      <geometry>
        <cylinder length="0.12" radius="0.013" />
      </geometry>
    </collision>
  </link>
  <joint
    name="RL_calf_joint"
    type="revolute">
    <origin
      xyz="0 0 -0.2"
      rpy="0 0 0" />
    <parent
      link="RL_thigh" />
    <child
      link="RL_calf" />
    <axis
      xyz="0 1 0" />
    <limit
      lower="-2.5"
      upper="-0.85"
      effort="35."
      velocity="32.0" />
  </joint>
  <link
    name="RL_calflower">
    <collision>
      <origin
        xyz="0 0 0"
        rpy="0 0 0" />
      <geometry>
        <cylinder length="0.065" radius="0.011" />
      </geometry>
    </collision>
  </link>
  <joint
    name="RL_calflower_joint"
    type="fixed">
    <origin
      xyz="0.020 0 -0.148"
      rpy="0 0.05 0" />
    <parent
      link="RL_calf" />
    <child
      link="RL_calflower" />
    <axis
      xyz="0 0 0" />
  </joint>
  <link
    name="RL_calflower1">
      <collision>
      <origin rpy="0 0 0" xyz="0 0 0.001" />
      <geometry>
        <cylinder length="0.03" radius="0.0155" />
      </geometry>
    </collision>
  </link>
  <joint
    name="RL_calflower1_joint"
    type="fixed">
    <origin
      xyz="-0.01 0 -0.04"
      rpy="0 0.48 0" />
    <parent
      link="RL_calflower" />
    <child
      link="RL_calflower1" />
    <axis
      xyz="0 0 0" />
  </joint>
  <link
    name="RL_foot">
    <inertial>
      <origin
        xyz="0 0 0"
        rpy="0 0 0" />
      <mass
        value="0.04" />
      <inertia
        ixx="9.6e-06"
        ixy="0"
        ixz="0"
        iyy="9.6e-06"
        iyz="0"
        izz="9.6e-06" />
    </inertial>
    <visual>
      <origin
        xyz="0 0 0"
        rpy="0 0 0" />
      <geometry>
        <mesh
          filename="package://urdf_tutorial/meshes/foot.stl" />
      </geometry>
      <material
        name="">
        <color
          rgba="1 1 1 1" />
      </material>
    </visual>
    <collision>
      <origin rpy="0 0 0" xyz="-0.002 0 0" />
      <geometry>
        <sphere radius="0.022" />
      </geometry>
    </collision>
  </link>
  <joint
    name="RL_foot_joint"
    type="fixed" dont_collapse="true">
    <origin
      xyz="0 0 -0.2112"
      rpy="0 0 0" />
    <parent
      link="RL_calf" />
    <child
      link="RL_foot" />
    <axis
      xyz="0 0 0" />
  </joint>
  <link
    name="RR_hip">
    <inertial>
      <origin
        xyz="-0.0544563980901653 0.0122230494514429 -3.3318566200452E-05"
        rpy="0 0 0" />
      <mass
        value="0.333458397795885" />
      <inertia
        ixx="0.000228898292913373"
        ixy="5.63887079795717E-06"
        ixz="-6.00777112902181E-08"
        iyy="0.000358700855536297"
        iyz="2.45226682486684E-07"
        izz="0.000209164381606462" />
    </inertial>
    <visual>
      <origin
        xyz="0 0 0"
        rpy="0 0 0" />
      <geometry>
        <mesh
          filename="package://urdf_tutorial/meshes/TOE_dog3/RR_hip.STL" />
      </geometry>
      <material
        name="">
        <color
          rgba="1 1 1 1" />
      </material>
    </visual>
    <collision>
      <origin rpy="1.5707963267948966 0 0" xyz="-0.064 0. 0" />
      <geometry>
        <cylinder length="0.08" radius="0.048" />
      </geometry>
    </collision>
  </link>
  <joint
    name="RR_hip_joint"
    type="revolute">
    <origin
      xyz="-0.136 -0.063 0"
      rpy="0 0 0" />
    <parent
      link="base" />
    <child
      link="RR_hip" />
    <axis
      xyz="1 0 0" />
    <limit
      lower="-1.0"
      upper="1.0"
      effort="20."
      velocity="20." />
  </joint>
  <link
    name="RR_thigh">
    <inertial>
      <origin
        xyz="-0.00179872498747159 0.0157556929216544 -0.0361368559942862"
        rpy="0 0 0" />
      <mass
        value="0.597702170804261" />
      <inertia
        ixx="0.00175679023858605"
        ixy="3.7636654390356E-07"
        ixz="-8.03965188721908E-05"
        iyy="0.0020682871887868"
        iyz="2.31975014127542E-06"
        izz="0.000356956578939868" />
    </inertial>
    <visual>
      <origin
        xyz="0 0 0"
        rpy="0 0 0" />
      <geometry>
        <mesh
          filename="package://urdf_tutorial/meshes/TOE_dog3/RR_thigh.STL" />
      </geometry>
      <material
        name="">
        <color
          rgba="1 1 1 1" />
      </material>
    </visual>
    <collision>
      <origin rpy="0 1.5707963267948966 0" xyz="0 0 -0.1065" />
      <geometry>
        <box size="0.11 0.0245 0.034" />
      </geometry>
    </collision>
  </link>
  <joint
    name="RR_thigh_joint"
    type="revolute">
    <origin
      xyz="-0.064 -0.0673 0"
      rpy="0 0 0" />
    <parent
      link="RR_hip" />
    <child
      link="RR_thigh" />
    <axis
      xyz="0 1 0" />
    <limit
      lower="-1.5"
      upper="2.5"
      effort="30."
      velocity="32.0" />
  </joint>
  <link
    name="RR_calf">
    <inertial>
      <origin
        xyz="0.00865673912254452 -4.16362152563798E-05 -0.0952663894238475"
        rpy="0 0 0" />
      <mass
        value="0.160684138940357" />
      <inertia
        ixx="0.000298759609040293"
        ixy="1.45139114638283E-08"
        ixz="2.43022230387997E-05"
        iyy="0.000309017747432289"
        iyz="4.7331900159905E-08"
        izz="1.56084268840318E-05" />
    </inertial>
    <visual>
      <origin
        xyz="0 0 0"
        rpy="0 0 0" />
      <geometry>
        <mesh
          filename="package://urdf_tutorial/meshes/TOE_dog3/RR_calf.STL" />
      </geometry>
      <material
        name="">
        <color
          rgba="1 1 1 1" />
      </material>
    </visual>
    <collision>
      <origin rpy="0 -0.2 0" xyz="0.01 0 -0.06" />
      <geometry>
        <cylinder length="0.12" radius="0.013" />
      </geometry>
    </collision>
  </link>
  <joint
    name="RR_calf_joint"
    type="revolute">
    <origin
      xyz="0 0 -0.2"
      rpy="0 0 0" />
    <parent
      link="RR_thigh" />
    <child
      link="RR_calf" />
    <axis
      xyz="0 1 0" />
    <limit
      lower="-2.5"
      upper="-0.85"
      effort="35."
      velocity="32.0" />
  </joint>
  <link
    name="RR_calflower">
    <collision>
      <origin rpy="0 0 0" xyz="0 0 0" />
      <geometry>
        <cylinder length="0.065" radius="0.011" />
      </geometry>
    </collision>
  </link>
  <joint
    name="RR_calflower_joint"
    type="fixed">
    <origin
      xyz="0.020 0 -0.148"
      rpy="0 0.05 0" />
    <parent
      link="RR_calf" />
    <child
      link="RR_calflower" />
    <axis
      xyz="0 0 0" />
  </joint>
  <link
    name="RR_calflower1">
        <collision>
      <origin rpy="0 0 0" xyz="0 0 0.001" />
      <geometry>
        <cylinder length="0.03" radius="0.0155" />
      </geometry>
    </collision>
  </link>
  <joint
    name="RR_calflower1_joint"
    type="fixed">
    <origin
      xyz="-0.01 0 -0.04"
      rpy="0 0.48 0" />
    <parent
      link="RR_calflower" />
    <child
      link="RR_calflower1" />
    <axis
      xyz="0 0 0" />
  </joint>
  <link
    name="RR_foot">
    <inertial>
      <origin
        xyz="0 0 0"
        rpy="0 0 0" />
      <mass
        value="0.04" />
      <inertia
        ixx="9.6e-06"
        ixy="0"
        ixz="0"
        iyy="9.6e-06"
        iyz="0"
        izz="9.6e-06" />
    </inertial>
    <visual>
      <origin
        xyz="0 0 0"
        rpy="0 0 0" />
      <geometry>
        <mesh
          filename="package://urdf_tutorial/meshes/foot.stl" />
      </geometry>
      <material
        name="">
        <color
          rgba="1 1 1 1" />
      </material>
    </visual>
    <collision>
      <origin rpy="0 0 0" xyz="-0.002 0 0" />
      <geometry>
        <sphere radius="0.022" />
      </geometry>
    </collision>
  </link>
  <joint
    name="RR_foot_joint"
    type="fixed" dont_collapse="true">
    <origin
      xyz="0 0 -0.2112"
      rpy="0 0 0" />
    <parent
      link="RR_calf" />
    <child
      link="RR_foot" />
    <axis
      xyz="0 0 0" />
  </joint>
<link
    name="imu">
    <inertial>
      <origin
        xyz="0 0 0"
        rpy="0 0 0" />
      <mass
        value="0" />
      <inertia
        ixx="0"
        ixy="0"
        ixz="0"
        iyy="0"
        iyz="0"
        izz="0" />
    </inertial>
  </link>
  <joint
    name="imu_joint"
    type="fixed">
    <origin
      xyz="0. 0 0."
      rpy="0 0 0" />
    <parent
      link="base" />
    <child
      link="imu" />
    <axis
      xyz="0 0 0" />
  </joint>
</robot>